Workbook

Sheet Error Log
A1: No | B1: Date | C1: Modality | D1: HHID | E1: uuid | F1: Enumerator | G1: Logged by: | H1: Comments | I1: Action Required | J1: Other comments | K1: Action Taken | L1: Closed?
A2: 1 | B2: 45153 | C2: F2F | D2: General | G2: Nicole | H2: Missing education and health information in Roster once marked as respondent | I2: Remove the relevant ${RESPYN} ='0' for PSex and Page; On Aug 16 night, all enumerators should get the updated form to continue | K2: Remove the relevant ${RESPYN} ='0' for PSex and Page in the F2F form | L2: Yes
A3: 2 | B3: 45155 | C3: Remote | D3: CAR12025 | E3: a5e3830e-1407-4d2e-8db2-2e8f603544e0 | F3: Bobby Jerry | G3: Nicole | H3: Ces ménages ont des dépenses alimentaires et des dépenses globales nulles - clarifier avec les enquêteurs si c'est vraiment le cas.
A4: 3 | B4: 45155 | C4: Remote | D4: CAR12023 | E4: fb1d81ed-082b-418a-a025-0c77a8547f00 | F4: Bobby Jerry | G4: Nicole
A5: 4 | B5: 45155 | C5: Remote | D5: CAR12020 | E5: ab819567-4404-4bef-9c9e-d2ea0647bdad | F5: Bobby Jerry | G5: Nicole
A6: 5 | B6: 45155 | C6: Remote | D6: CAR12028 | E6: 3bf291e9-8fad-49ec-876b-51b348ada272 | F6: Bobby Jerry | G6: Nicole
A7: 6 | B7: 45155 | C7: Remote | D7: CAR22182 | E7: 22b8e38b-e37c-408d-badc-d831f1571da9 | F7: Bobby Jerry | G7: Nicole
A8: 7 | B8: 45155 | C8: Remote | D8: CAR12101 | E8: 24adbb66-fa56-4ea9-976c-079826e0e96d | F8: Gbissigui Otokpio Dasiel | G8: Nicole
A9: 8 | B9: 45155 | C9: Remote | D9: CAR12102 | E9: 63087f64-5694-44a3-a8e8-0e83c6ff7da9 | F9: Gbissigui Otokpio Dasiel | G9: Nicole
A10: 9 | B10: 45155 | C10: Remote | D10: CAR12095 | E10: a6c5d9cf-3d05-4372-bfbc-498896114368 | F10: Gbissigui Otokpio Dasiel | G10: Nicole
A11: 10 | B11: 45155 | C11: Remote | D11: CAR12086 | E11: ecbc7d6d-4e33-4f1d-84f6-6963df1636a0 | F11: Gbissigui Otokpio Dasiel | G11: Nicole
A12: 11 | B12: 45155 | C12: Remote | D12: CAR12087 | E12: 35680358-9a13-42c4-8766-11187e397de2 | F12: Gbissigui Otokpio Dasiel | G12: Nicole
A13: 12 | B13: 45155 | C13: Remote | D13: CAR12088 | E13: 3364e795-1292-4980-9063-055bb83880a6 | F13: Gbissigui Otokpio Dasiel | G13: Nicole
A14: 13 | B14: 45155 | C14: Remote | D14: CAR12165 | E14: b2b4fb2b-6889-4597-a45e-7bbd1c2a4747 | F14: Goumba Suzie | G14: Nicole
A15: 14 | B15: 45155 | C15: Remote | D15: CAR12178 | E15: b3b256a3-28ef-4eaa-8083-584380d22091 | F15: Goumba Suzie | G15: Nicole
... A21: 20 | B21: 45155 | C21: Remote | D21: CAR12208 | E21: 45af6aca-6503-473e-8f58-93406d0d856a | F21: Ngrekamba Nancy Carole | G21: Nicole
A22: 20 | B22: 45155 | C22: Remote | D22: General | G22: Nicole | H22: Parmi les 154 enquêtes à distance complétées, 2 ont indiqué qu'il n'y avait pas de téléphone dans l'enquête d'inscription, et 38 ont été marquées comme n'ayant pas de couverture réseau - précisez pourquoi cela s'est produit.

Sheet Duplicates
A1: No | B1: Date | C1: Modality | D1: HHID | E1: uuid | F1: Enumerator | G1: RESPAge | H1: RESPSex | I1: HHSize | J1: Logged by: | K1: Responses | L1: Other comments | M1: Action Taken | N1: Closed?
A2: 1 | B2: 45153 | C2: F2F | D2: CAR2101286 | E2: ebf3e2ec-0845-4494-a2a1-e99579dfc503 | F2: FROKOM Brillant | G2: 27 | H2: Female | I2: 4 | J2: Nicole | K2: No | L2: Menage non confirmé | M2: Joel
B3: 45153 | D3: CAR2101286 | E3: fb8d0f9c-7de7-4fdf-82d2-0e87ad49d3b7 | F3: GOUNOUMOUNDJOU Simplice | G3: 58 | H3: Female | I3: 3 | J3: Nicole | K3: OK | L3: Menage confirmé | M3: Joel
A4: 2 | B4: 45153 | C4: Remote | D4: CAR12018 | E4: 660124db-5995-445a-8f6e-04c7e5f6d40f | F4: BOBBY Jerry | G4: 45 | H4: Male | I4: 9 | J4: Nicole | K4: OK | L4: Menage confirmé | M4: Joel
B5: 45153 | D5: CAR12018 | E5: 381287e8-f887-43d3-b9f1-a42716dc635a | F5: GBISSIGUI OTOKPIO Dasiel | G5: 36 | H5: Male | I5: 6 | J5: Nicole | K5: no | L5: Menage non confirmé | M5: Joel
A6: 3 | B6: 45153 | C6: Remote | D6: CAR1397 | E6: 223259ab-c01c-47bc-b0d5-796ff4d57385 | F6: BINGA Jordan | G6: 20 | H6: Male | I6: 4 | J6: Nicole
B7: 45153 | D7: CAR1397 | E7: e4849d7c-d2d7-4f99-99dc-83c7194d1c05 | F7: KOGBA-Line Benita | G7: 45 | H7: Female | I7: 5 | J7: Nicole
A8: 4 | B8: 45155 | C8: F2F | D8: CAR1101184 | E8: 91fc8ca3-07ca-44ca-b3a1-2ad8c32b8cbc | F8: KOPIRI DOLE Noella | G8: 40 | H8: Female | I8: 7 | J8: Nicole | K8: ok | L8: Menage confirmé | M8: Joel
B9: 45155 | D9: CAR1101184 | E9: b7e66a81-e2cb-4302-ba92-dd13f37aa444 | F9: KOPIRI DOLE Noella | G9: 18 | H9: Female | I9: 3 | J9: Nicole | K9: No | L9: Menage non confirmé | M9: Joel
A10: 5 | B10: 45155 | C10: F2F | D10: CAR110124 | E10: 8f33fdbe-297c-4803-ad67-ef3ee05bc16b | F10: KOPIRI DOLE Noella | G10: 27 | H10: Male | I10: 6 | J10: Nicole | K10: No | L10: Menage non confirmé | M10: Joel
B11: 45155 | D11: CAR110124 | E11: 908e22b7-7f32-4895-a692-688130d3cc71 | F11: NELO Odilon | G11: 55 | H11: Male | I11: 6 | J11: Nicole | K11: OK | L11: Menage confirmé | M11: Joel
A12: 6 | B12: 45155 | C12: F2F | D12: CAR110178 | E12: d740218c-2456-4b58-98ce-aa9dad266143 | F12: ENZA INGUERE Danielle | G12: 80 | H12: Female | I12: 7 | J12: Nicole | K12: OK | L12: Menage confirmé | M12: Joel
B13: 45155 | D13: CAR110178 | E13: c67e2f6a-049c-440d-8bc8-7cdfa27bc362 | F13: ENZA INGUERE Danielle | G13: 25 | H13: Female | I13: 6 | J13: Nicole | K13: No | L13: Menage non confirmé | M13: Joel
A14: 7 | B14: 45160 | C14: F2F | D14: CAR2101193 | E14: d4bbfd45-f05d-45cf-9dc6-12e7377f8e41 | F14: BAGUIWE Aaron | G14: 23 | H14: Female | I14: 5 | J14: Nicole | K14: No | L14: Menage non confirmé | M14: Joel
B15: 45160 | D15: CAR2101193 | E15: cd1189de-9f11-4c0d-a514-993a9cd85c81 | F15: BAGUIWE Aaron | G15: 35 | H15: Female | I15: 6 | J15: Nicole | K15: OK | L15: Menage confirmé | M15: Joel
A16: 8 | B16: 45160 | C16: F2F | D16: CAR2101240 | E16: 503d1959-0c21-4e63-af00-253c92f45361 | F16: BAGUIWE Aaron | G16: 45 | H16: Male | I16: 6 | J16: Nicole | K16: OK | L16: Menage confirmé | M16: Joel
B17: 45160 | D17: CAR2101240 | E17: 99edc3a3-8821-41e9-920d-6bcec8c9b610 | F17: FROKOM Brillant | G17: 34 | H17: Male | I17: 5 | J17: Nicole | K17: No | L17: Menage non confirmé | M17: Joel
A18: 9 | B18: 45160 | C18: F2F | D18: CAR210291 | E18: 4aeda82e-0c2b-448f-8671-1319ea87b6a2 | F18: BAGUIWE Aaron | G18: 65 | H18: Female | I18: 6 | J18: Nicole | K18: OK | L18: Menage confirmé | M18: Joel
B19: 45160 | D19: CAR210291 | E19: ab4330fa-262d-4a36-8c78-505b468021ea | F19: BAGUIWE Aaron | G19: 34 | H19: Female | I19: 6 | J19: Nicole | K19: No | L19: Menage non confirmé | M19: Joel
A20: 10 | B20: 45160 | C20: F2F | D20: CAR210453 | E20: ec863daa-93b5-4480-a1fa-d51d02d7b1e5 | F20: BAGUIWE Aaron | G20: 35 | H20: Male | I20: 10 | J20: Nicole | K20: No | L20: Menage non confirmé | M20: Joel
B21: 45160 | D21: CAR210453 | E21: dd4757ab-aade-403d-b722-a52bffb53daa | F21: BAGUIWE Aaron | G21: 20 | H21: Female | I21: 5 | J21: Nicole | K21: OK | L21: Menage confirmé | M21: Joel
A22: 11 | B22: 45162 | C22: F2F | D22: CAR2101070 | E22: 01cfa17b-1d3f-4d89-b85d-98a20c09891d | F22: DEGANAÏ DEDE Igor Tiburce | G22: 40 | H22: Female | I22: 5 | J22: Nicole | K22: ok | L22: Menage confirmé | M22: Joel
B23: 45162 | D23: CAR2101070 | E23: c1cc6eaf-8c73-41c2-af34-a6b789558be4 | F23: TOUTOU Alain | G23: 47 | H23: Female | I23: 4 | J23: Nicole | K23: No | L23: Menage non confirmé | M23: Joel
A24: 12 | B24: 45162 | C24: F2F | D24: CAR210214 | E24: 712d3672-c29a-4a59-8b8c-028737b85bc7 | F24: BAGUIWE Aaron | G24: 37 | H24: Male | I24: 7 | J24: Nicole | K24: OK | L24: Menage confirmé | M24: Joel
B25: 45162 | D25: CAR210214 | E25: afa1f32e-ea9d-4c3a-a9f2-d1f4925dd690 | F25: NANIBET Chadly | G25: 93 | H25: Male | I25: 4 | J25: Nicole | K25: No | L25: Menage non confirmé | M25: Joel
A26: 13 | B26: 45162 | C26: F2F | D26: CAR210400 | E26: 68034e7d-9505-4817-873c-56739aa6c97a | F26: NANIBET Chadly | G26: 23 | H26: Female | I26: 2 | J26: Nicole | K26: OK | L26: Menage confirmé | M26: Joel
B27: 45162 | D27: CAR210400 | E27: 0f7e454d-47ec-4bd5-bd11-7a62795caf69 | F27: BAGUIWE Aaron | G27: 23 | H27: Female | I27: 5 | J27: Nicole | K27: No | L27: Menage non confirmé | M27: Joel
A28: 14 | B28: 45187 | C28: Remote | D28: CAR12066 | E28: 7b2b1308-4a44-4e14-98e5-2c30e623a98a | F28: BANGBALAMA Hyacinthe | G28: 70 | H28: Female | I28: 6 | J28: Nicole | L28: Drop this (Second interview/entry)
B29: 45187 | D29: CAR12066 | E29: 6c9dbf75-bcbd-41fa-9449-880803960143 | F29: BANGBALAMA Hyacinthe | G29: 70 | H29: Female | I29: 6 | J29: Nicole
A30: 15 | B30: 45187 | C30: Remote | D30: CAR22110 | E30: 3a630476-d138-4549-a7df-29c2088008d3 | F30: BOBBY Jerry | G30: 35 | H30: Female | I30: 6 | J30: Nicole | K30: OK | L30: Menage confirmé | M30: Joel
B31: 45187 | D31: CAR22110 | E31: 772479cf-d44b-4da3-a43b-f00990a3073a | F31: BOBBY Jerry | G31: 40 | H31: Female | I31: 9 | J31: Nicole | K31: No | L31: Menage non confirmé | M31: Joel
A32: 16 | B32: 45187 | C32: Remote | D32: CAR2342 | E32: f811149d-e74e-40fd-8f8b-77f9594de006 | F32: NGREKAMBA Nancy Carole | G32: 19 | H32: Female | I32: 8 | J32: Nicole
B33: 45187 | D33: CAR2342 | E33: 3ae7eecd-4b54-4f08-a08c-19df286bdcca | F33: NGREKAMBA Nancy Carole | G33: 29 | H33: Male | I33: 5 | J33: Nicole
A34: 17 | B34: 45187 | C34: Remote | D34: CAR2498 | E34: 4d1e8624-ba7f-4cb7-911c-d57c16928df2 | F34: KOGBA-Line Benita | G34: 60 | H34: Male | I34: 13 | J34: Nicole | L34: Drop this one based on time of submission this is duplicate.
B35: 45187 | D35: CAR2498 | E35: d69f7b4a-278e-4d39-aed1-d8fca8bea084 | F35: KOGBA-Line Benita | G35: 60 | H35: Male | I35: 13 | J35: Nicole

Sheet Roster Error
A1: HH_Index | B1: HHID | C1: EnuName_Display | D1: RESPAge | E1: RESPSex | F1: RESPStatus | G1: S_hh_head_sex | H1: S_hh_head_marital | I1: ___uuid | J1: Logged by: | K1: Question/clarification | L1: ___index in Roster/Individual Dataset | M1: Action Required on Roster Data Correction | N1: Action Taken | O1: Other comments | P1: Closed?
A2: 3 | B2: CAR2101279 | C2: BAGUIWE Aaron | D2: 50 | E2: Female | F2: Single | G2: Male | H2: No | I2: ea37c865-1940-42fb-a108-fdf7da2944dd | J2: Nicole | K2: These Households have 0 or more than 1 person marked as respondent, should only be one | L2: 17 is the respondent
A3: 25 | B3: CAR2101283 | C3: TOUTOU Alain | D3: 28 | E3: Female | F3: Single | G3: Female | H3: No | I3: fd6531d4-70d7-423f-a9fb-73e2edf3fa75 | J3: Nicole
A4: 71 | B4: CAR2101271 | C4: FROKOM Brillant | D4: 40 | E4: Male | F4: Cohabitating | G4: Male | H4: No | I4: 5121b0fb-1c5f-4a92-921f-a969dcde630b | J4: Nicole
A5: 72 | B5: CAR2101270 | C5: FROKOM Brillant | D5: 19 | E5: Female | F5: Divorced/Separated | G5: Male | H5: No | I5: 4cc5ecb9-52da-42c3-aa6b-5b14dddc94e5 | J5: Nicole
A6: 73 | B6: CAR210372 | C6: FROKOM Brillant | D6: 40 | E6: Male | F6: Cohabitating | G6: Male | H6: No | I6: 9a324c13-3ef3-40e5-a22a-d6ba55556601 | J6: Nicole
A7: 74 | B7: CAR2101272 | C7: FROKOM Brillant | D7: 46 | E7: Male | F7: Cohabitating | G7: Male | H7: No | I7: d3830ead-03b7-4ce7-962e-42430db5095f | J7: Nicole
A8: 75 | B8: CAR2101262 | C8: FROKOM Brillant | D8: 35 | E8: Female | F8: Cohabitating | G8: Male | H8: Yes | I8: 0a0bb1f0-6661-46f0-be09-ac82b844eb82 | J8: Nicole
A9: 76 | B9: CAR210362 | C9: FROKOM Brillant | D9: 41 | E9: Male | F9: Cohabitating | G9: Female | H9: No | I9: 7da97d24-48a0-4b72-8088-c206610974b0 | J9: Nicole
A10: 77 | B10: CAR210363 | C10: FROKOM Brillant | D10: 61 | E10: Female | F10: Widowed | G10: Female | H10: No | I10: 070e88d9-3fb4-4582-a76a-7ab6d2df8806 | J10: Nicole
A11: 78 | B11: CAR210356 | C11: FROKOM Brillant | D11: 18 | E11: Male | F11: Single | G11: Male | H11: No | I11: e1112a10-2f72-43f6-84a9-56109149250b | J11: Nicole
A12: 79 | B12: CAR2101282 | C12: FROKOM Brillant | D12: 45 | E12: Female | F12: Widowed | G12: Female | H12: No | I12: 1f8db9f3-cb97-430e-9181-d12c8f633d21 | J12: Nicole
A13: 84 | B13: CAR2101263 | C13: FROKOM Brillant | D13: 30 | E13: Female | F13: Widowed | G13: Female | H13: No | I13: a4aa8554-03ea-40ed-9b3d-83db1ac74c5d | J13: Nicole
A14: 86 | B14: CAR210405 | C14: FROKOM Brillant | D14: 53 | E14: Female | F14: Cohabitating | G14: Male | H14: No | I14: eb5cb0ee-081f-45e8-a8ab-d916d4a1db65 | J14: Nicole
A15: 88 | B15: CAR2101295 | C15: FROKOM Brillant | D15: 49 | E15: Male | F15: Cohabitating | G15: Male | H15: No | I15: b7610b83-b834-49a3-8aaa-fa7b4ee6ab9e | J15: Nicole

Sheet Missing Roster
A1: No. | B1: Enumerator | C1: HHID | D1: HH_Index | E1: PRelationHHH Answered in Roster Dataset | F1: Information about respondent in Main | I1: HH info in Listing Survey | K1: ___index in Roster Dataset | L1: Comments | M1: Correct Respondent in Roster Dataset (Answer Yes/No here). Only one person should be marked as Respondent per Household | N1: Action Required | O1: Other comments
F2: RESPAge | G2: RESPSex | H2: RESPStatus | I2: S_hh_head_sex | J2: S_hh_head_marital | P2: Action Taken | Q2: Closed?
A3: 1 | B3: =VLOOKUP(D3,'Roster Error'!$A$2:$H$15,3,FALSE) -> BAGUIWE Aaron | C3: =VLOOKUP(D3,'Roster Error'!$A$2:$H$15,2,FALSE) -> CAR2101279 | D3: 3 | E3: Spouse/partner | F3: =VLOOKUP(D3,'Roster Error'!$A$2:$H$15,4,FALSE) -> 50 | G3: =VLOOKUP(D3,'Roster Error'!$A$2:$H$15,5,FALSE) -> Female | H3: =VLOOKUP(D3,'Roster Error'!$A$2:$H$15,6,FALSE) -> Single | I3: =VLOOKUP(D3,'Roster Error'!$A$2:$H$15,7,FALSE) -> Male | J3: =VLOOKUP(D3,'Roster Error'!$A$2:$H$15,8,FALSE) -> No | K3: 17 | L3: These Individuals were marked all as respondents in the Roster dataset (more than one each household) - follow up with them all in the
A4: 2 | B4: =VLOOKUP(D4,'Roster Error'!$A$2:$H$15,3,FALSE) -> BAGUIWE Aaron | C4: =VLOOKUP(D4,'Roster Error'!$A$2:$H$15,2,FALSE) -> CAR2101279 | D4: 3 | E4: Spouse/partner | F4: =VLOOKUP(D4,'Roster Error'!$A$2:$H$15,4,FALSE) -> 50 | G4: =VLOOKUP(D4,'Roster Error'!$A$2:$H$15,5,FALSE) -> Female | H4: =VLOOKUP(D4,'Roster Error'!$A$2:$H$15,6,FALSE) -> Single | I4: =VLOOKUP(D4,'Roster Error'!$A$2:$H$15,7,FALSE) -> Male | J4: =VLOOKUP(D4,'Roster Error'!$A$2:$H$15,8,FALSE) -> No | K4: 24
A5: 3 | B5: =VLOOKUP(D5,'Roster Error'!$A$2:$H$15,3,FALSE) -> FROKOM Brillant | C5: =VLOOKUP(D5,'Roster Error'!$A$2:$H$15,2,FALSE) -> CAR2101271 | D5: 71 | E5: Head of household | F5: =VLOOKUP(D5,'Roster Error'!$A$2:$H$15,4,FALSE) -> 40 | G5: =VLOOKUP(D5,'Roster Error'!$A$2:$H$15,5,FALSE) -> Male | H5: =VLOOKUP(D5,'Roster Error'!$A$2:$H$15,6,FALSE) -> Cohabitating | I5: =VLOOKUP(D5,'Roster Error'!$A$2:$H$15,7,FALSE) -> Male | J5: =VLOOKUP(D5,'Roster Error'!$A$2:$H$15,8,FALSE) -> No | K5: 397
A6: 4 | B6: =VLOOKUP(D6,'Roster Error'!$A$2:$H$15,3,FALSE) -> FROKOM Brillant | C6: =VLOOKUP(D6,'Roster Error'!$A$2:$H$15,2,FALSE) -> CAR2101271 | D6: 71 | E6: Head of household | F6: =VLOOKUP(D6,'Roster Error'!$A$2:$H$15,4,FALSE) -> 40 | G6: =VLOOKUP(D6,'Roster Error'!$A$2:$H$15,5,FALSE) -> Male | H6: =VLOOKUP(D6,'Roster Error'!$A$2:$H$15,6,FALSE) -> Cohabitating | I6: =VLOOKUP(D6,'Roster Error'!$A$2:$H$15,7,FALSE) -> Male | J6: =VLOOKUP(D6,'Roster Error'!$A$2:$H$15,8,FALSE) -> No | K6: 398
A7: 5 | B7: =VLOOKUP(D7,'Roster Error'!$A$2:$H$15,3,FALSE) -> FROKOM Brillant | C7: =VLOOKUP(D7,'Roster Error'!$A$2:$H$15,2,FALSE) -> CAR2101271 | D7: 71 | E7: Head of household | F7: =VLOOKUP(D7,'Roster Error'!$A$2:$H$15,4,FALSE) -> 40 | G7: =VLOOKUP(D7,'Roster Error'!$A$2:$H$15,5,FALSE) -> Male | H7: =VLOOKUP(D7,'Roster Error'!$A$2:$H$15,6,FALSE) -> Cohabitating | I7: =VLOOKUP(D7,'Roster Error'!$A$2:$H$15,7,FALSE) -> Male | J7: =VLOOKUP(D7,'Roster Error'!$A$2:$H$15,8,FALSE) -> No | K7: 399
A8: 6 | B8: =VLOOKUP(D8,'Roster Error'!$A$2:$H$15,3,FALSE) -> FROKOM Brillant | C8: =VLOOKUP(D8,'Roster Error'!$A$2:$H$15,2,FALSE) -> CAR2101271 | D8: 71 | E8: Head of household | F8: =VLOOKUP(D8,'Roster Error'!$A$2:$H$15,4,FALSE) -> 40 | G8: =VLOOKUP(D8,'Roster Error'!$A$2:$H$15,5,FALSE) -> Male | H8: =VLOOKUP(D8,'Roster Error'!$A$2:$H$15,6,FALSE) -> Cohabitating | I8: =VLOOKUP(D8,'Roster Error'!$A$2:$H$15,7,FALSE) -> Male | J8: =VLOOKUP(D8,'Roster Error'!$A$2:$H$15,8,FALSE) -> No | K8: 400
A9: 7 | B9: =VLOOKUP(D9,'Roster Error'!$A$2:$H$15,3,FALSE) -> FROKOM Brillant | C9: =VLOOKUP(D9,'Roster Error'!$A$2:$H$15,2,FALSE) -> CAR2101271 | D9: 71 | E9: Head of household | F9: =VLOOKUP(D9,'Roster Error'!$A$2:$H$15,4,FALSE) -> 40 | G9: =VLOOKUP(D9,'Roster Error'!$A$2:$H$15,5,FALSE) -> Male | H9: =VLOOKUP(D9,'Roster Error'!$A$2:$H$15,6,FALSE) -> Cohabitating | I9: =VLOOKUP(D9,'Roster Error'!$A$2:$H$15,7,FALSE) -> Male | J9: =VLOOKUP(D9,'Roster Error'!$A$2:$H$15,8,FALSE) -> No | K9: 401
A10: 8 | B10: =VLOOKUP(D10,'Roster Error'!$A$2:$H$15,3,FALSE) -> FROKOM Brillant | C10: =VLOOKUP(D10,'Roster Error'!$A$2:$H$15,2,FALSE) -> CAR2101271 | D10: 71 | E10: Mother/Father | F10: =VLOOKUP(D10,'Roster Error'!$A$2:$H$15,4,FALSE) -> 40 | G10: =VLOOKUP(D10,'Roster Error'!$A$2:$H$15,5,FALSE) -> Male | H10: =VLOOKUP(D10,'Roster Error'!$A$2:$H$15,6,FALSE) -> Cohabitating | I10: =VLOOKUP(D10,'Roster Error'!$A$2:$H$15,7,FALSE) -> Male | J10: =VLOOKUP(D10,'Roster Error'!$A$2:$H$15,8,FALSE) -> No | K10: 402
A11: 9 | B11: =VLOOKUP(D11,'Roster Error'!$A$2:$H$15,3,FALSE) -> FROKOM Brillant | C11: =VLOOKUP(D11,'Roster Error'!$A$2:$H$15,2,FALSE) -> CAR2101271 | D11: 71 | E11: Spouse/partner | F11: =VLOOKUP(D11,'Roster Error'!$A$2:$H$15,4,FALSE) -> 40 | G11: =VLOOKUP(D11,'Roster Error'!$A$2:$H$15,5,FALSE) -> Male | H11: =VLOOKUP(D11,'Roster Error'!$A$2:$H$15,6,FALSE) -> Cohabitating | I11: =VLOOKUP(D11,'Roster Error'!$A$2:$H$15,7,FALSE) -> Male | J11: =VLOOKUP(D11,'Roster Error'!$A$2:$H$15,8,FALSE) -> No | K11: 403
A12: 10 | B12: =VLOOKUP(D12,'Roster Error'!$A$2:$H$15,3,FALSE) -> FROKOM Brillant | C12: =VLOOKUP(D12,'Roster Error'!$A$2:$H$15,2,FALSE) -> CAR2101271 | D12: 71 | E12: Brother/sister | F12: =VLOOKUP(D12,'Roster Error'!$A$2:$H$15,4,FALSE) -> 40 | G12: =VLOOKUP(D12,'Roster Error'!$A$2:$H$15,5,FALSE) -> Male | H12: =VLOOKUP(D12,'Roster Error'!$A$2:$H$15,6,FALSE) -> Cohabitating | I12: =VLOOKUP(D12,'Roster Error'!$A$2:$H$15,7,FALSE) -> Male | J12: =VLOOKUP(D12,'Roster Error'!$A$2:$H$15,8,FALSE) -> No | K12: 404
A13: 11 | B13: =VLOOKUP(D13,'Roster Error'!$A$2:$H$15,3,FALSE) -> FROKOM Brillant | C13: =VLOOKUP(D13,'Roster Error'!$A$2:$H$15,2,FALSE) -> CAR2101270 | D13: 72 | E13: Son/daughter | F13: =VLOOKUP(D13,'Roster Error'!$A$2:$H$15,4,FALSE) -> 19 | G13: =VLOOKUP(D13,'Roster Error'!$A$2:$H$15,5,FALSE) -> Female | H13: =VLOOKUP(D13,'Roster Error'!$A$2:$H$15,6,FALSE) -> Divorced/Separated | I13: =VLOOKUP(D13,'Roster Error'!$A$2:$H$15,7,FALSE) -> Male | J13: =VLOOKUP(D13,'Roster Error'!$A$2:$H$15,8,FALSE) -> No | K13: 405
A14: 12 | B14: =VLOOKUP(D14,'Roster Error'!$A$2:$H$15,3,FALSE) -> FROKOM Brillant | C14: =VLOOKUP(D14,'Roster Error'!$A$2:$H$15,2,FALSE) -> CAR2101270 | D14: 72 | E14: Spouse/partner | F14: =VLOOKUP(D14,'Roster Error'!$A$2:$H$15,4,FALSE) -> 19 | G14: =VLOOKUP(D14,'Roster Error'!$A$2:$H$15,5,FALSE) -> Female | H14: =VLOOKUP(D14,'Roster Error'!$A$2:$H$15,6,FALSE) -> Divorced/Separated | I14: =VLOOKUP(D14,'Roster Error'!$A$2:$H$15,7,FALSE) -> Male | J14: =VLOOKUP(D14,'Roster Error'!$A$2:$H$15,8,FALSE) -> No | K14: 406
A15: 13 | B15: =VLOOKUP(D15,'Roster Error'!$A$2:$H$15,3,FALSE) -> FROKOM Brillant | C15: =VLOOKUP(D15,'Roster Error'!$A$2:$H$15,2,FALSE) -> CAR2101270 | D15: 72 | E15: Mother/Father | F15: =VLOOKUP(D15,'Roster Error'!$A$2:$H$15,4,FALSE) -> 19 | G15: =VLOOKUP(D15,'Roster Error'!$A$2:$H$15,5,FALSE) -> Female | H15: =VLOOKUP(D15,'Roster Error'!$A$2:$H$15,6,FALSE) -> Divorced/Separated | I15: =VLOOKUP(D15,'Roster Error'!$A$2:$H$15,7,FALSE) -> Male | J15: =VLOOKUP(D15,'Roster Error'!$A$2:$H$15,8,FALSE) -> No | K15: 407
... A82: 80 | B82: =VLOOKUP(D82,'Roster Error'!$A$2:$H$15,3,FALSE) -> FROKOM Brillant | C82: =VLOOKUP(D82,'Roster Error'!$A$2:$H$15,2,FALSE) -> CAR2101295 | D82: 88 | E82: Son/daughter | F82: =VLOOKUP(D82,'Roster Error'!$A$2:$H$15,4,FALSE) -> 49 | G82: =VLOOKUP(D82,'Roster Error'!$A$2:$H$15,5,FALSE) -> Male | H82: =VLOOKUP(D82,'Roster Error'!$A$2:$H$15,6,FALSE) -> Cohabitating | I82: =VLOOKUP(D82,'Roster Error'!$A$2:$H$15,7,FALSE) -> Male | J82: =VLOOKUP(D82,'Roster Error'!$A$2:$H$15,8,FALSE) -> No | K82: 526
A83: 81 | B83: BAGUIWE Aaron | C83: CAR210357 | D83: 1 | E83: Spouse/partner | F83: 67 | G83: Female | H83: Single | I83: Male | J83: No | K83: 1 | L83: One member per household marked as Respondent to follow up with missing information
A84: 82 | B84: BAGUIWE Aaron | C84: CAR210359 | D84: 2 | E84: Son/daughter | F84: 19 | G84: Female | H84: Single | I84: Female | J84: No | K84: 8
A85: 83 | B85: BAGUIWE Aaron | C85: CAR2101280 | D85: 4 | E85: Spouse/partner | F85: 30 | G85: Female | H85: Single | I85: Male | J85: No | K85: 25
A86: 84 | B86: BAGUIWE Aaron | C86: CAR210378 | D86: 5 | E86: Head of household | F86: 50 | G86: Male | H86: Single | I86: Male | J86: No | K86: 30
A87: 85 | B87: BAGUIWE Aaron | C87: CAR2101264 | D87: 6 | E87: Head of household | F87: 61 | G87: Female | H87: Widowed | I87: Female | J87: No | K87: 35
A88: 86 | B88: BAGUIWE Aaron | C88: CAR2101268 | D88: 7 | E88: Head of household | F88: 58 | G88: Male | H88: Married | I88: Male | J88: Yes | K88: 40
A89: 87 | B89: BAGUIWE Aaron | C89: CAR2101269 | D89: 8 | E89: Head of household | F89: 36 | G89: Male | H89: Single | I89: Male | J89: No | K89: 46
A90: 88 | B90: BAGUIWE Aaron | C90: CAR210214 | D90: 9 | E90: Head of household | F90: 37 | G90: Male | H90: Single | I90: Male | J90: No | K90: 53
A91: 89 | B91: BAGUIWE Aaron | C91: CAR210400 | D91: 10 | E91: Spouse/partner | F91: 23 | G91: Female | H91: Single | I91: Male | J91: No | K91: 60
A92: 90 | B92: BAGUIWE Aaron | C92: CAR2101284 | D92: 11 | E92: Head of household | F92: 29 | G92: Male | H92: Single | I92: Male | J92: No | K92: 65
A93: 91 | B93: BAGUIWE Aaron | C93: CAR2101301 | D93: 12 | E93: Head of household | F93: 26 | G93: Male | H93: Single | I93: Male | J93: No | K93: 69
A94: 92 | B94: BAGUIWE Aaron | C94: CAR2101285 | D94: 13 | E94: Spouse/partner | F94: 50 | G94: Female | H94: Single | I94: Male | J94: No | K94: 73
A95: 93 | B95: BAGUIWE Aaron | C95: CAR210396 | D95: 14 | E95: Spouse/partner | F95: 44 | G95: Female | H95: Married | I95: Male | J95: Yes | K95: 77
... A153: 151 | B153: FROKOM Brillant | C153: CAR210384 | D153: 82 | E153: Head of household | F153: 62 | G153: Female | H153: Divorced/Separated | I153: Female | J153: No | K153: 478
A154: 152 | D154: 83 | E154: Head of household | G154: . | H154: . | I154: . | J154: . | K154: 484
A155: 153 | B155: FROKOM Brillant | C155: CAR210393 | D155: 85 | E155: Head of household | F155: 48 | G155: Female | H155: Widowed | I155: Female | J155: No | K155: 493
A156: 154 | B156: FROKOM Brillant | C156: CAR210392 | D156: 87 | E156: Head of household | F156: 26 | G156: Male | H156: Cohabitating | I156: Male | J156: No | K156: 516
A157: 155 | B157: FROKOM Brillant | C157: CAR210406 | D157: 89 | E157: Head of household | F157: 35 | G157: Male | H157: Cohabitating | I157: Male | J157: No | K157: 527
A158: 156 | B158: FROKOM Brillant | C158: CAR210391 | D158: 90 | E158: Head of household | F158: 53 | G158: Male | H158: Cohabitating | I158: Male | J158: No | K158: 533
A159: 157 | B159: FROKOM Brillant | C159: CAR2101364 | D159: 91 | E159: Head of household | F159: 50 | G159: Female | H159: Widowed | I159: Female | J159: No | K159: 540
A160: 158 | B160: FROKOM Brillant | C160: CAR2101382 | D160: 92 | E160: Head of household | F160: 42 | G160: Male | H160: Divorced/Separated | I160: Male | J160: Yes | K160: 544
A161: 159 | B161: FROKOM Brillant | C161: CAR2101362 | D161: 93 | E161: Head of household | F161: 60 | G161: Male | H161: Cohabitating | I161: Female | J161: Yes | K161: 553
A162: 160 | B162: FROKOM Brillant | C162: CAR2101363 | D162: 94 | E162: Head of household | F162: 23 | G162: Male | H162: Cohabitating | I162: Male | J162: Yes | K162: 555
A163: 161 | B163: FROKOM Brillant | C163: CAR210462 | D163: 95 | E163: Head of household | F163: 29 | G163: Female | H163: Cohabitating | I163: Female | J163: Yes | K163: 558
...

Sheet Other Specify Clarifications
A1: HHID | B1: EnuName_Display | C1: HHHOccupation | D1: HHIncFirst_oth | E1: Clarification
A2: CAR110252 | B2: Nelo Odilon | C2: Cultivatrice | D2: Agriculture
A3: CAR210465 | B3: Toutou Alain | C3: Cherché à Manger | D3: Cherché à Manger
A4: CAR12029 | B4: Bobby Jerry | C4: Couturier | D4: Coturier
A5: CAR1101156 | B5: Nelo Odilon | C5: Couturier | D5: Couturier
A6: CAR2101262 | B6: Frokom Brillant | C6: Cultivateur | D6: Cultiver
A7: CAR22119 | B7: Ngrekamba Nancy Carole | C7: Cultivateure | D7: Cultuvateure
A8: CAR110129 | B8: Nelo Odilon | C8: Extracteur De Sable | D8: Extracteur De Sable
A9: CAR2101383 | B9: Baguiwe Aaron | C9: Cultivateur | D9: Jardin
A10: CAR2101384 | B10: Toutou Alain | C10: Jardinier | D10: Jardin
A11: CAR2101378 | B11: Gounoumoundjou Simplice | C11: Aucune | D11: Le PèRe Et Tous Les Enfants Ramassent Et Vendent De Fagots Afin Subvenir Aux Besoins Du MéNage
A12: CAR1101202 | B12: Nelo Odilon | C12: MaçOn | D12: MaçOnnerie
A13: CAR1101206 | B13: Nguinda | C13: MaçOn | D13: MaçOnnerie
... A29: CAR110103 | B29: Nelo Odilon | C29: Trafiquants | D29: Trafic
